Traceback (most recent call last):
  File "/usr/local/python/3.12.1/lib/python3.12/site-packages/jupyter_cache/executors/utils.py", line 58, in single_nb_execution
    executenb(
  File "/home/codespace/.local/lib/python3.12/site-packages/nbclient/client.py", line 1314, in execute
    return NotebookClient(nb=nb, resources=resources, km=km, **kwargs).execute()
           ^^^^^^^^^^^^^^^^^^^^^^^^^^^^^^^^^^^^^^^^^^^^^^^^^^^^^^^^^^^^^^^^^^^^^
  File "/home/codespace/.local/lib/python3.12/site-packages/jupyter_core/utils/__init__.py", line 165, in wrapped
    return loop.run_until_complete(inner)
           ^^^^^^^^^^^^^^^^^^^^^^^^^^^^^^
  File "/usr/local/python/3.12.1/lib/python3.12/asyncio/base_events.py", line 684, in run_until_complete
    return future.result()
           ^^^^^^^^^^^^^^^
  File "/home/codespace/.local/lib/python3.12/site-packages/nbclient/client.py", line 709, in async_execute
    await self.async_execute_cell(
  File "/home/codespace/.local/lib/python3.12/site-packages/nbclient/client.py", line 1062, in async_execute_cell
    await self._check_raise_for_error(cell, cell_index, exec_reply)
  File "/home/codespace/.local/lib/python3.12/site-packages/nbclient/client.py", line 918, in _check_raise_for_error
    raise CellExecutionError.from_cell_and_msg(cell, exec_reply_content)
nbclient.exceptions.CellExecutionError: An error occurred while executing the following cell:
------------------
import psycopg2
import pandas as pd
from tabulate import tabulate

# Koneksi ke database PostgreSQL
PG_HOST = "posgesqlpendata23-175-posgresqlpendata23-175.h.aivencloud.com"
PG_PORT = "17047"
PG_NAME = "defaultdb"
PG_USER = "avnadmin"
PG_PASS = "AVNS_XfGwRG6_6e5BdqZXovg"

try:
    # Membuat koneksi
    conn = psycopg2.connect(
        host=PG_HOST,
        port=PG_PORT,
        dbname=PG_NAME,
        user=PG_USER,
        password=PG_PASS,
        sslmode="require"
    )
    cur = conn.cursor()

    # Menjalankan query
    cur.execute("SELECT * FROM irisposgre.posgre;")  # Ganti dengan nama skema & tabel yang benar
    rows = cur.fetchall()

    # Mengambil nama kolom
    col_names = [desc[0] for desc in cur.description]

    # Menampilkan hasil dalam bentuk tabel
    df = pd.DataFrame(rows, columns=col_names)
    print(tabulate(df, headers="keys", tablefmt="psql"))

except Exception as e:
    print("Error:", e)

finally:
    # Menutup koneksi
    if cur:
        cur.close()
    if conn:
        conn.close()

------------------

----- stdout -----
Error: could not translate host name "posgesqlpendata23-175-posgresqlpendata23-175.h.aivencloud.com" to address: Name or service not known
------------------

[0;31m---------------------------------------------------------------------------[0m
[0;31mNameError[0m                                 Traceback (most recent call last)
Cell [0;32mIn[4], line 40[0m
[1;32m     36[0m     [38;5;28mprint[39m([38;5;124m"[39m[38;5;124mError:[39m[38;5;124m"[39m, e)
[1;32m     38[0m [38;5;28;01mfinally[39;00m:
[1;32m     39[0m     [38;5;66;03m# Menutup koneksi[39;00m
[0;32m---> 40[0m     [38;5;28;01mif[39;00m [43mcur[49m:
[1;32m     41[0m         cur[38;5;241m.[39mclose()
[1;32m     42[0m     [38;5;28;01mif[39;00m conn:

[0;31mNameError[0m: name 'cur' is not defined

